<?xml version="1.0"?>
<robot xmlns:xacro="http://ros.org/wiki/xacro" name="aquanaute">

    <material name="blue">
        <color rgba="0 0 0.8 1"/>
    </material>
    <material name="red">
        <color rgba="0.8 0 0 1"/>
    </material>
    <material name="green">
        <color rgba="0 0.8 0 0.5"/>
    </material>
    <material name="cyan">
        <color rgba="0 0.6 0.6 1"/>
    </material>
    <material name="yellow">
        <color rgba="0.8 0.8 0 1"/>
    </material>
    <material name="purple">
        <color rgba="0.5 0 0.5 1"/>
    </material>
    <material name="white">
        <color rgba="1 1 1 1"/>
    </material>
    <material name="gray">
        <color rgba="0.35 0.35 0.35 1"/>
    </material>
    <material name="black">
        <color rgba="0 0 0 1"/>
    </material>

    <!-- * * * Link Definitions * * * -->
    <link name="base_link">
        <visual>
            <origin rpy="0 0 0" xyz="0 0 0"/>
            <geometry>
                <sphere radius="0.001"/>
            </geometry>
            <material name="blue"/>
        </visual>
    </link>

    <link name="boat_link">
        <inertial>
            <origin xyz="0 0 0" rpy="0 0 0"/>
            <mass value="38.718"/>
            <inertia ixx="16.283" ixy="0.008" ixz="0.458" iyy="19.728" iyz="0.0" izz="33.013"/>
        </inertial>

        <collision>
            <origin xyz="0 0 0" rpy="0 0 0"/>
            <geometry>
                <mesh filename="package://aquanaute_description/models/meshes/Assambly_aquanaute.stl"/>
            </geometry>
        </collision>

        <visual>
            <origin rpy="0 0 0" xyz="0 0 0"/>
            <geometry>
                <mesh filename="package://aquanaute_description/models/meshes/Assambly_aquanaute.stl"/>
            </geometry>
            <material name="gray"/>
        </visual>
    </link>

    <link name="motor_link">
        <inertial>
            <origin xyz="-0.133 0 -0.391" rpy="0 0 0"/>
            <mass value="6.6"/>
            <inertia ixx="0.072" ixy="3.604" ixz="-0.011" iyy="0.111" iyz="5.484" izz="0.042"/>
        </inertial>

        <collision>
            <origin xyz="0 0 0" rpy="0 0 0"/>
            <geometry>
                <mesh filename="package://aquanaute_description/models/meshes/Motor.stl"/>
            </geometry>
        </collision>

        <visual>
            <origin rpy="0 0 0" xyz="0 0 0"/>
            <geometry>
                <mesh filename="package://aquanaute_description/models/meshes/Motor.stl"/>
            </geometry>
            <material name="purple"/>
        </visual>
    </link>

    <link name="propeller_link">
        <inertial>
            <origin xyz="-0.034 0 0" rpy="0 0 0"/>
            <mass value="0.233"/>
            <!--<inertia ixx="1.441e-04" ixy="4.406e-09" ixz="0.00" iyy="1.760e-04"	iyz="2.373e-06" izz="1.961e-04"/>-->
            <inertia ixx="0.00" ixy="0.00" ixz="0.00" iyy="0.00" iyz="0.00" izz="0.00"/>
        </inertial>

        <collision>
            <origin xyz="0 0 0" rpy="0 0 0"/>
            <geometry>
                <mesh filename="package://aquanaute_description/models/meshes/Propeller.stl"/>
            </geometry>
        </collision>

        <visual>
            <origin rpy="0 0 0" xyz="0 0 0"/>
            <geometry>
                <mesh filename="package://aquanaute_description/models/meshes/Propeller.stl"/>
            </geometry>
            <material name="blue"/>
        </visual>
    </link>

    <link name="imu_link">
        <visual>
            <origin rpy="0 0 0" xyz="0 0 0"/>
            <geometry>
                <cylinder radius="0.04" length="0.05"/>
            </geometry>
            <material name="cyan"/>
        </visual>
    </link>

    <!-- * * * Joint Definitions * * * -->
    <joint name="boat_base_joint" type="fixed">
        <parent link="base_link"/>
        <child link="boat_link"/>
        <origin xyz="0 0 0.25" rpy="0 0 0"/>
    </joint>

    <joint name="motor_boat_joint" type="revolute">
        <parent link="boat_link"/>
        <child link="motor_link"/>
        <origin xyz="-0.905 0.0 0.115" rpy="0 0 0"/>
        <axis xyz="0 0 1"/>
        <limit effort="-1" velocity="-1" lower="-0.9" upper="0.9"/>
        <dynamics damping="0.0000001"/>
    </joint>

    <joint name="propeller_motor_joint" type="revolute">
        <parent link="motor_link"/>
        <child link="propeller_link"/>
        <origin xyz="-0.265 0 -0.42" rpy="0 0 0"/>
        <axis xyz="1 0 0"/>
        <limit effort="-1" velocity="-1" lower="-1e+16" upper="1e+16"/>
        <dynamics damping="0.0000001"/>
    </joint>

    <joint name="imu_boat_joint" type="fixed">
        <parent link="boat_link"/>
        <child link="imu_link"/>
        <origin xyz="0 0 0.04" rpy="0 0 0"/>
    </joint>
</robot>
